Workbook

Sheet Executive Summary
A1: CRM Customer Feedback Analysis & Feature Prioritization
A2: SYNTHETIC DATA — all records are randomly generated for a fictional CRM company; no real customers.
A3: Executive summary — fictional B2B SaaS CRM, 12-month window (Oct 2025 – Sep 2026)
A5: KPI | B5: Value
A6: Total feedback records | B6: =COUNTA('Cleaned Feedback'!$A$2:$A$1501)
A7: Unique customers (static) | B7: 326
A8: Negative feedback % | B8: =COUNTIF('Cleaned Feedback'!$J$2:$J$1501,"Negative")/COUNTA('Cleaned Feedback'!$A$2:$A$1501)
A9: High/Critical severity % | B9: =(COUNTIF('Cleaned Feedback'!$K$2:$K$1501,"High")+COUNTIF('Cleaned Feedback'!$K$2:$K$1501,"Critical"))/COUNTA('Cleaned Feedback'!$A$2:$A$1501)
A10: Feature requests | B10: =COUNTIF('Cleaned Feedback'!$H$2:$H$1501,"Feature Request")
A13: Top 3 RICE priorities | B13: RICE Score | C13: Recommendation
A14: =INDEX('RICE Calculations'!$B$9:$B$20,MATCH(1,'RICE Calculations'!$J$9:$J$20,0)) | B14: =INDEX('RICE Calculations'!$I$9:$I$20,MATCH(1,'RICE Calculations'!$J$9:$J$20,0)) | C14: Build now (next planning cycle)
A15: =INDEX('RICE Calculations'!$B$9:$B$20,MATCH(2,'RICE Calculations'!$J$9:$J$20,0)) | B15: =INDEX('RICE Calculations'!$I$9:$I$20,MATCH(2,'RICE Calculations'!$J$9:$J$20,0)) | C15: Build now (next planning cycle)
A16: =INDEX('RICE Calculations'!$B$9:$B$20,MATCH(3,'RICE Calculations'!$J$9:$J$20,0)) | B16: =INDEX('RICE Calculations'!$I$9:$I$20,MATCH(3,'RICE Calculations'!$J$9:$J$20,0)) | C16: Build now (next planning cycle)
A19: Observed (synthetic data):
A20: • 1,500 records from 326 of 420 accounts (77.6%).
A21: • Most-reported complaint theme: Unreliable contact imports (102 records, 86 accounts).
A22: • Largest feature area by volume: Workflow Automation (301 records).
A23: Interpretation: volume reflects reports, not prevalence; the 420-account base is the only denominator.
A24: Hypothesis: fixing top-ranked reliability issues (import, workflow monitoring) may reduce support load — to be validated.
A25: Limitations: synthetic data, estimated Impact/Confidence/Effort, RICE ranks are not objective facts.

Sheet Raw Feedback
A1: feedback_id | B1: customer_id | C1: submission_date | D1: feedback_source | E1: subscription_plan | F1: customer_segment | G1: feature_area | H1: feedback_category | I1: feedback_text | J1: sentiment | K1: severity | L1: customer_impact
A2: FB-00001 | B2: CUST-0152 | C2: 2025-10-01 | D2: Support Ticket | E2: Enterprise | F2: Enterprise | G2: Integrations | H2: Integration Issue | I2: Frustrated with this one. Webhook delivery is unreliable and there is no retry or log we can inspect. Support suggested logging it here. | J2: Negative | K2: High | L2: Workflow Slowdown
A3: FB-00002 | B3: CUST-0157 | C3: 2025-10-01 | D3: Support Ticket | E3: Starter | F3: SMB | G3: User Interface | H3: Performance Issue | I3: Our team keeps running into this. Since the redesign there is more slow page transitions on older laptops. It happens about 30 times a week for our team of 34. Support suggested logging it here. | J3: NEGATIVE | K3: High | L3: Workflow Slowdown
A4: FB-00003 | B4: CUST-0025 | C4: 2025-10-02 | D4: Support Ticket | E4: Enterprise | F4: Enterprise | G4: Integrations | H4: Integration Issue | I4: Frustrated with this one. After the token expires, Gmail sync stops with no warning. Our RevOps lead flagged it while onboarding 6 new users. | J4: Negative | K4: Low | L4: Minor Inconvenience
A5: FB-00004 | B5: CUST-0027 | C5: 2025-10-02 | D5: Support Ticket | E5: Professional | F5: SMB | G5: Contact Management | H5: Bug | I5: The contact CSV import rejects files with accented characters in names. We estimate we lose roughly 26 hours a month on this. Is there a workaround? | J5: Negative | K5: Medium | L5: Blocks Key Task
A6: FB-00005 | B6: CUST-0003 | C6: 2025-10-03 | D6: Support Ticket | E6: Starter | F6: Mid-Market | G6: User Interface | H6: Usability Issue | I6: Raising this again after our last business review. Too many clicks to reach common screens because of the settings navigation. So far 50 people on our side have reported it. | J6: Negative | K6: Low | L6: Minor Inconvenience
A7: FB-00006 | B7: CUST-0021 | C7: 2025-10-03 | D7: In-App Feedback | E7: Professional | F7: Mid-Market | G7: Workflow Automation | H7: Bug | I7: We are hitting workflow failures: emails don't send and nobody gets notified. It affects our renewal process every cycle. | J7: Neutral | K7: Medium | L7: Minor Inconvenience
A8: FB-00007 | B8: CUST-0060 | C8: 2025-10-04 | D8: In-App Feedback | E8: Starter | F8: SMB | G8: User Interface | H8: Usability Issue | I8: Noting this during onboarding. The navigation menu is cluttered and I can never find the setting I need. We estimate we lose roughly 32 hours a month on this. | J8: Neutral | K8: High | L8: Revenue/Operations Risk
A9: FB-00008 | B9: CUST-0139 | C9: 2025-10-04 | D9: Feature Request | E9: Professional | F9: Mid-Market | G9: Lead Management | H9: Feature Request | I9: Overall we like the product. Right now reps rank leads by gut feel; automated lead scoring would fix that. Happy to beta test. | J9: Positive | K9: High | L9: Workflow Slowdown
A10: FB-00009 | B10: CUST-0036 | C10: 2025-10-04 | D10: Customer Survey | E10: Starter | F10: SMB | G10: Lead Management | H10: USABILITY ISSUE | I10: Frustrated with this one. Setting up lead routing rules takes too many steps and the options don't cover territories. We estimate we lose roughly 58 hours a month on this. We need a fix before renewal. | J10: Negative | K10: Low | L10: Minor Inconvenience
A11: FB-00010 | B11: CUST-0269 | C11: 2025-10-04 | D11: Feature Request | E11: Professional | F11: SMB | G11: Reporting | H11: Bug | I11: FYI for the product team. Our Excel export drops formatting and shows dates as numbers. So far 65 people on our side have reported it. | J11: Neutral | K11: High | L11: Blocks Key Task
A12: FB-00011 | B12: CUST-0313 | C12: 2025-10-05 | D12: Support Ticket | E12: Starter | F12: SMB | G12: Reporting | H12: Performance Issue | I12: Raising this again after our last business review. Our dashboard loading spins for a minute before showing any chart. It happens about 20 times a week for our team of 111. Is there a workaround? | J12: Negative | K12: Medium | L12: Blocks Key Task
... A178: FB-00177 | B178: CUST-0091 | C178: 2025-11-20 | D178: Customer Survey | E178: Professional | F178: SMB | G178: Reporting | H178: Feature Request | I178: Feedback from our monthly review. Please add a custom report builder; today an analyst rebuilds the same report every week. So far 74 people on our side have reported it. | J178: Neutral | K178: Low | L178: Minor Inconvenience
A179: FB-00178 | B179: CUST-0065 | C179: 2025-11-21 | D179: In-App Feedback | E179: Professional | F179: Mid-Market | G179: Lead Management | H179: Bug | I179: Escalating on behalf of our ops lead. Web form submissions keep creating lead de-duplication failures, and reps end up calling the same prospect twice. Is there a workaround? | J179: Negative | K179: Medium
A180: FB-00179 | B180: CUST-0188 | C180: 2025-11-21 | D180: Support Ticket | E180: Enterprise | F180: Mid-Market | G180: Workflow Automation | H180: Bug | I180: Raising this again after our last business review. We found workflow failures only because a customer complained. Our marketing ops owner flagged it while onboarding 98 new users. We need a fix before renewal. | J180: Negative | K180: High | L180: Workflow Slowdown
A181: FB-00180 | B181: CUST-0403 | C181: 2025-11-22 | D181: In-App Feedback | E181: Starter | F181: SMB | G181: User Interface | H181: Performance Issue | I181: Since the redesign there is more slow page transitions on older laptops. It affects our lead handoff process every cycle. | J181: Negative | K181: Critical | L181: Revenue/Operations Risk
A182: FB-00181 | B182: CUST-0003 | C182: 2025-11-22 | D182: Support Ticket | E182: Starter | F182: Mid-Market | G182: Reporting | H182: Bug | I182: Finance can't rely on the CSV export of reports; totals don't match the screen. It happens about 38 times a week for our team of 74. | J182: Neutral | K182: High | L182: Blocks Key Task
A183: FB-00182 | B183: CUST-0251 | C183: 2025-11-22 | D183: Support Ticket | E183: Professional | F183: mid-market | G183: Lead Management | H183: Bug | I183: This has been a recurring problem for us. We are seeing duplicated leads when a lead arrives from both the website and a trade-show list. It affects our lead handoff process every cycle. Please look into it soon. | J183: Negative | K183: Medium | L183: Workflow Slowdown
A184: FB-00183 | B184: CUST-0187 | C184: 2025-11-22 | D184: In-App Feedback | E184: Enterprise | F184: Mid-Market | G184: User Interface | H184: Performance Issue | I184: Noting this during onboarding. We notice slow page transitions whenever more than a few tabs are open. So far 102 people on our side have reported it. | J184: Neutral | K184: Medium | L184: Minor Inconvenience
A185: FB-00184 | B185: CUST-0201 | C185: 2025-11-22 | D185: Support Ticket | E185: Starter | F185: SMB | G185: User Interface | H185: Feature Request | I185: Quick note from our admin. Requesting offline mobile access so reps can log activity right after a meeting. Happy to join a feedback call. | J185: Neutral | K185: Medium | L185: Workflow Slowdown
A186: FB-00185 | B186: CUST-0069 | C186: 2025-11-23 | D186: In-App Feedback | E186: Starter | F186: Mid-Market | G186: User Interface | H186: Usability Issue | I186: This has been a recurring problem for us. Too many clicks to reach common screens because of the navigation menu. We estimate we lose roughly 46 hours a month on this. | J186: Negative | K186: Medium | L186: Minor Inconvenience
A187: FB-00186 | B187: CUST-0318 | C187: 2025-11-23 | D187: Support Ticket | E187: Starter | F187: SMB | G187: Reporting | H187: Performance Issue | I187: The report load time is painfully slow with a full year of data. | J187: Positive | K187: Low | L187: Minor Inconvenience
A188: FB-00187 | B188: CUST-0286 | C188: 2025-11-23 | D188: Support Ticket | E188: Enterprise | F188: Enterprise | G188: Integrations | H188: Integration Issue | I188: We keep hitting API timeouts during nightly syncs with our data warehouse. It affects our onboarding process every cycle. | J188: Negative | K188: High | L188: Workflow Slowdown
A189: FB-00188 | B189: CUST-0342 | C189: 2025-11-24 | D189: Support Ticket | E189: Enterprise | F189: Enterprise | G189: Integrations | H189: Integration Issue | I189: Our team keeps running into this. Hard to debug: webhook delivery fail with vague error codes. So far 57 people on our side have reported it. | J189: Negative | K189: Critical | L189: Blocks Key Task
A190: FB-00189 | B190: CUST-0239 | C190: 2025-11-25 | D190: Feature Request | E190: Professional | F190: MID-MARKET | G190: Reporting | H190: Feature Request | I190: Overall we like the product. We need report scheduling so non-technical managers can create their own views. It happens about 27 times a week for our team of 74. Keep up the good work. | J190: Positive | K190: Medium | L190: Minor Inconvenience
A191: FB-00190 | B191: CUST-0277 | C191: 2025-11-25 | D191: Support Ticket | E191: Professional | F191: Mid-Market | G191: Integrations | H191: Feature Request | I191: Sharing this from our team. Lack of a marketing automation connector is a gap versus other CRMs we evaluated. It affects our onboarding process every cycle. Let us know if you need examples. | J191: Neutral | K191: High | L191: Workflow Slowdown
... A220: FB-00219 | B220: CUST-0175 | C220: 2025-12-04 | D220: Feature Request | E220: Professional | F220: Mid-Market | G220: Reporting | H220: Feature Request | I220: Please add a custom report builder; today an analyst rebuilds the same report every week. Happy to join a feedback call. | J220: Neutral | K220: High | L220: Minor Inconvenience
A221: FB-00220 | B221: CUST-0314 | C221: 2025-12-06 | D221: Support Ticket | E221: Enterprise | F221: Mid-Market | G221: Contact Management | H221: Bug | I221: Our spreadsheet import scrambles phone and email columns even after we map them correctly. We estimate we lose roughly 49 hours a month on this. Happy to join a feedback call. | J221: Neutral | K221: Medium
A222: FB-00221 | B222: CUST-0060 | C222: 2025-12-06 | D222: In-App Feedback | E222: Starter | F222: SMB | G222: Reporting | H222: Performance Issue | I222: Happy with most of the product. The dashboard refresh is painfully slow with a full year of data. Thanks to the team. | J222: Positive | K222: Low | L222: Workflow Slowdown
A223: FB-00222 | B223: CUST-0121 | C223: 2025-12-06 | D223: In-App Feedback | E223: Starter | F223: SMB | G223: Reporting | H223: Performance Issue | I223: Not what we expected for the price. Dashboard refresh got noticeably worse over the last few months. | J223: Negative | K223: Medium | L223: Workflow Slowdown
A224: FB-00223 | B224: CUST-0091 | C224: 2025-12-06 | D224: Feature Request | E224: Professional | F224: SMB | G224: Workflow Automation | H224: Feature Request | I224: Recent updates have been a nice improvement. Adding multi-level approvals is a blocker for our finance team. It affects our quarterly planning process every cycle. Thanks to the team. | J224: Positive | K224: Low | L224: Workflow Slowdown
A225: FB-00224 | B225: CUST-0187 | C225: 2025-12-07 | D225: In-App Feedback | E225: Enterprise | F225: Mid-Market | G225: Reporting | H225: Performance Issue | I225: Quick note from our admin. Report load time got noticeably worse over the last few months. | J225: Neutral | K225: High | L225: Blocks Key Task
A226: FB-00225 | B226: CUST-0216 | C226: 2025-12-07 | D226: Support Ticket | E226: Starter | F226: MID-MARKET | G226: Lead Management | H226: Bug | I226: Frustrated with this one. There are duplicated leads across our pipeline views and nobody knows which record is the source of truth. Our marketing ops owner flagged it while onboarding 46 new users. We need a fix before renewal. | J226: Negative | K226: Medium | L226: Minor Inconvenience
A227: FB-00226 | B227: CUST-0102 | C227: 2025-12-08 | D227: Support Ticket | E227: Professional | F227: Mid-Market | G227: Contact Management | H227: Bug | I227: Escalating on behalf of our ops lead. The spreadsheet import fails halfway through with a generic error and no row-level detail. It affects our weekly pipeline review process every cycle. Is there a workaround? | J227: Negative | K227: High | L227: Blocks Key Task
A228: FB-00227 | B228: CUST-0198 | C228: 2025-12-09 | D228: In-App Feedback | E228: Starter | F228: SMB | G228: Reporting | H228: Performance Issue | I228: FYI for the product team. Report load time got noticeably worse over the last few months. So far 66 people on our side have reported it. | J228: Neutral | K228: Low | L228: Minor Inconvenience
A229: FB-00228 | B229: CUST-0153 | C229: 2025-12-09 | D229: Feature Request | E229: Enterprise | F229: Enterprise | G229: Reporting | H229: Feature Request | I229: We need scheduled report emails so non-technical managers can create their own views. It affects our onboarding process every cycle. | J229: Positive | K229: Medium | L229: Minor Inconvenience
A230: FB-00229 | B230: CUST-0092 | C230: 2025-12-09 | D230: Feature Request | E230: Professional | F230: Mid-Market | G230: User Interface | H230: Feature Request | I230: Great support experience recently. Requesting bulk actions on lists across every list view. Thanks to the team. | J230: Positive | K230: Low | L230: Minor Inconvenience
A231: FB-00230 | B231: CUST-0391 | C231: 2025-12-09 | D231: Customer Survey | E231: Enterprise | F231: Mid-Market | G231: User Interface | H231: Feature Request | I231: Quick note from our admin. Admins ask for multi-select actions every time we reorganize territories. | J231: Neutral | K231: Medium | L231: Blocks Key Task
A232: FB-00231 | B232: CUST-0121 | C232: 2025-12-10 | D232: Support Ticket | E232: Starter | F232: SMB | G232: User Interface | H232: Usability Issue | I232: The settings navigation changed and nobody told us where things moved. It affects our weekly pipeline review process every cycle. Is there a workaround? | J232: Negative | K232: Low | L232: Workflow Slowdown
A233: FB-00232 | B233: CUST-0330 | C233: 2025-12-10 | D233: Feature Request | E233: Professional | F233: Mid-Market | G233: Integrations | H233: Feature Request | I233: Quick note from our admin. Requesting a native accounting integration to remove manual re-entry. So far 26 people on our side have reported it. | J233: Neutral | K233: Medium | L233: Workflow Slowdown
...

Sheet Cleaned Feedback
A1: feedback_id | B1: customer_id | C1: submission_date | D1: feedback_source | E1: subscription_plan | F1: customer_segment | G1: feature_area | H1: feedback_category | I1: feedback_text | J1: sentiment | K1: severity | L1: customer_impact | M1: issue_theme | N1: issue_theme_label | O1: month
A2: FB-00001 | B2: CUST-0152 | C2: 45931 | D2: Support Ticket | E2: Enterprise | F2: Enterprise | G2: Integrations | H2: Integration Issue | I2: Frustrated with this one. Webhook delivery is unreliable and there is no retry or log we can inspect. Support suggested logging it here. | J2: Negative | K2: High | L2: Workflow Slowdown | M2: int_api | N2: API limits and webhook failures | O2: 2025-10
A3: FB-00002 | B3: CUST-0157 | C3: 45931 | D3: Support Ticket | E3: Starter | F3: SMB | G3: User Interface | H3: Performance Issue | I3: Our team keeps running into this. Since the redesign there is more slow page transitions on older laptops. It happens about 30 times a week for our team of 34. Support suggested logging it here. | J3: Negative | K3: High | L3: Workflow Slowdown | M3: ui_perf | N3: Laggy pages | O3: 2025-10
A4: FB-00003 | B4: CUST-0025 | C4: 45932 | D4: Support Ticket | E4: Enterprise | F4: Enterprise | G4: Integrations | H4: Integration Issue | I4: Frustrated with this one. After the token expires, Gmail sync stops with no warning. Our RevOps lead flagged it while onboarding 6 new users. | J4: Negative | K4: Low | L4: Minor Inconvenience | M4: int_email | N4: Email and calendar sync drops | O4: 2025-10
A5: FB-00004 | B5: CUST-0027 | C5: 45932 | D5: Support Ticket | E5: Professional | F5: SMB | G5: Contact Management | H5: Bug | I5: The contact CSV import rejects files with accented characters in names. We estimate we lose roughly 26 hours a month on this. Is there a workaround? | J5: Negative | K5: Medium | L5: Blocks Key Task | M5: contact_import | N5: Unreliable contact imports | O5: 2025-10
A6: FB-00005 | B6: CUST-0003 | C6: 45933 | D6: Support Ticket | E6: Starter | F6: Mid-Market | G6: User Interface | H6: Usability Issue | I6: Raising this again after our last business review. Too many clicks to reach common screens because of the settings navigation. So far 50 people on our side have reported it. | J6: Negative | K6: Low | L6: Minor Inconvenience | M6: ui_nav | N6: Cluttered navigation | O6: 2025-10
A7: FB-00006 | B7: CUST-0021 | C7: 45933 | D7: In-App Feedback | E7: Professional | F7: Mid-Market | G7: Workflow Automation | H7: Bug | I7: We are hitting workflow failures: emails don't send and nobody gets notified. It affects our renewal process every cycle. | J7: Neutral | K7: Medium | L7: Minor Inconvenience | M7: wf_fail | N7: Workflows failing silently | O7: 2025-10
A8: FB-00007 | B8: CUST-0060 | C8: 45934 | D8: In-App Feedback | E8: Starter | F8: SMB | G8: User Interface | H8: Usability Issue | I8: Noting this during onboarding. The navigation menu is cluttered and I can never find the setting I need. We estimate we lose roughly 32 hours a month on this. | J8: Neutral | K8: High | L8: Revenue/Operations Risk | M8: ui_nav | N8: Cluttered navigation | O8: 2025-10
A9: FB-00008 | B9: CUST-0139 | C9: 45934 | D9: Feature Request | E9: Professional | F9: Mid-Market | G9: Lead Management | H9: Feature Request | I9: Overall we like the product. Right now reps rank leads by gut feel; automated lead scoring would fix that. Happy to beta test. | J9: Positive | K9: High | L9: Workflow Slowdown | M9: lead_score | N9: Automated lead scoring | O9: 2025-10
A10: FB-00009 | B10: CUST-0036 | C10: 45934 | D10: Customer Survey | E10: Starter | F10: SMB | G10: Lead Management | H10: Usability Issue | I10: Frustrated with this one. Setting up lead routing rules takes too many steps and the options don't cover territories. We estimate we lose roughly 58 hours a month on this. We need a fix before renewal. | J10: Negative | K10: Low | L10: Minor Inconvenience | M10: lead_assign | N10: Lead routing is inflexible | O10: 2025-10
A11: FB-00010 | B11: CUST-0269 | C11: 45934 | D11: Feature Request | E11: Professional | F11: SMB | G11: Reporting | H11: Bug | I11: FYI for the product team. Our Excel export drops formatting and shows dates as numbers. So far 65 people on our side have reported it. | J11: Neutral | K11: High | L11: Blocks Key Task | M11: rep_export | N11: Broken report exports | O11: 2025-10
A12: FB-00011 | B12: CUST-0313 | C12: 45935 | D12: Support Ticket | E12: Starter | F12: SMB | G12: Reporting | H12: Performance Issue | I12: Raising this again after our last business review. Our dashboard loading spins for a minute before showing any chart. It happens about 20 times a week for our team of 111. Is there a workaround? | J12: Negative | K12: Medium | L12: Blocks Key Task | M12: rep_slow | N12: Slow dashboards | O12: 2025-10
A13: FB-00012 | B13: CUST-0404 | C13: 45935 | D13: In-App Feedback | E13: Starter | F13: SMB | G13: Reporting | H13: Feature Request | I13: Quick note from our admin. We need a custom report builder so non-technical managers can create their own views. Our finance analyst flagged it while onboarding 34 new users. Let us know if you need examples. | J13: Neutral | K13: Low | L13: Minor Inconvenience | M13: rep_custom | N13: Custom and scheduled reports | O13: 2025-10
... A1501: FB-01500 | B1501: CUST-0339 | C1501: 46295 | D1501: Support Ticket | E1501: Professional | F1501: Mid-Market | G1501: Integrations | H1501: Integration Issue | I1501: Our team keeps running into this. We keep hitting webhook delivery during nightly syncs with our data warehouse. It affects our onboarding process every cycle. Support suggested logging it here. | J1501: Negative | K1501: Medium | L1501: Blocks Key Task | M1501: int_api | N1501: API limits and webhook failures | O1501: 2026-09

Sheet Feedback Analysis
A1: Feedback Analysis
A2: SYNTHETIC DATA — all records are randomly generated for a fictional CRM company; no real customers.
A3: Record counts are live COUNTIF formulas on 'Cleaned Feedback'. Unique-customer counts are computed in Python (static). Volume ≠ customer prevalence.
A5: Feature Area | B5: Feedback Records | C5: % of Records | D5: Unique Customers (static)
A6: Workflow Automation | B6: =COUNTIF('Cleaned Feedback'!$G$2:$G$1501,A6) | C6: =B6/COUNTA('Cleaned Feedback'!$A$2:$A$1501) | D6: 175
A7: Integrations | B7: =COUNTIF('Cleaned Feedback'!$G$2:$G$1501,A7) | C7: =B7/COUNTA('Cleaned Feedback'!$A$2:$A$1501) | D7: 147
A8: Contact Management | B8: =COUNTIF('Cleaned Feedback'!$G$2:$G$1501,A8) | C8: =B8/COUNTA('Cleaned Feedback'!$A$2:$A$1501) | D8: 160
A9: Lead Management | B9: =COUNTIF('Cleaned Feedback'!$G$2:$G$1501,A9) | C9: =B9/COUNTA('Cleaned Feedback'!$A$2:$A$1501) | D9: 153
A10: Reporting | B10: =COUNTIF('Cleaned Feedback'!$G$2:$G$1501,A10) | C10: =B10/COUNTA('Cleaned Feedback'!$A$2:$A$1501) | D10: 138
A11: User Interface | B11: =COUNTIF('Cleaned Feedback'!$G$2:$G$1501,A11) | C11: =B11/COUNTA('Cleaned Feedback'!$A$2:$A$1501) | D11: 140
A14: Feedback Category | B14: Feedback Records | C14: % of Records | D14: Unique Customers (static)
A15: Feature Request | B15: =COUNTIF('Cleaned Feedback'!$H$2:$H$1501,A15) | C15: =B15/COUNTA('Cleaned Feedback'!$A$2:$A$1501) | D15: 241
A16: Bug | B16: =COUNTIF('Cleaned Feedback'!$H$2:$H$1501,A16) | C16: =B16/COUNTA('Cleaned Feedback'!$A$2:$A$1501) | D16: 193
A17: Usability Issue | B17: =COUNTIF('Cleaned Feedback'!$H$2:$H$1501,A17) | C17: =B17/COUNTA('Cleaned Feedback'!$A$2:$A$1501) | D17: 136
A18: Performance Issue | B18: =COUNTIF('Cleaned Feedback'!$H$2:$H$1501,A18) | C18: =B18/COUNTA('Cleaned Feedback'!$A$2:$A$1501) | D18: 125
A19: Integration Issue | B19: =COUNTIF('Cleaned Feedback'!$H$2:$H$1501,A19) | C19: =B19/COUNTA('Cleaned Feedback'!$A$2:$A$1501) | D19: 105
A22: Sentiment | B22: Feedback Records | C22: % of Records | D22: Unique Customers (static)
A23: Negative | B23: =COUNTIF('Cleaned Feedback'!$J$2:$J$1501,A23) | C23: =B23/COUNTA('Cleaned Feedback'!$A$2:$A$1501) | D23: 257
A24: Neutral | B24: =COUNTIF('Cleaned Feedback'!$J$2:$J$1501,A24) | C24: =B24/COUNTA('Cleaned Feedback'!$A$2:$A$1501) | D24: 241
A25: Positive | B25: =COUNTIF('Cleaned Feedback'!$J$2:$J$1501,A25) | C25: =B25/COUNTA('Cleaned Feedback'!$A$2:$A$1501) | D25: 140
A28: Severity | B28: Feedback Records | C28: % of Records | D28: Unique Customers (static)
A29: Low | B29: =COUNTIF('Cleaned Feedback'!$K$2:$K$1501,A29) | C29: =B29/COUNTA('Cleaned Feedback'!$A$2:$A$1501) | D29: 248
A30: Medium | B30: =COUNTIF('Cleaned Feedback'!$K$2:$K$1501,A30) | C30: =B30/COUNTA('Cleaned Feedback'!$A$2:$A$1501) | D30: 239
A31: High | B31: =COUNTIF('Cleaned Feedback'!$K$2:$K$1501,A31) | C31: =B31/COUNTA('Cleaned Feedback'!$A$2:$A$1501) | D31: 170
A32: Critical | B32: =COUNTIF('Cleaned Feedback'!$K$2:$K$1501,A32) | C32: =B32/COUNTA('Cleaned Feedback'!$A$2:$A$1501) | D32: 75
A35: Subscription Plan | B35: Feedback Records | C35: % of Records | D35: Unique Customers (static)
A36: Professional | B36: =COUNTIF('Cleaned Feedback'!$E$2:$E$1501,A36) | C36: =B36/COUNTA('Cleaned Feedback'!$A$2:$A$1501) | D36: 145
A37: Starter | B37: =COUNTIF('Cleaned Feedback'!$E$2:$E$1501,A37) | C37: =B37/COUNTA('Cleaned Feedback'!$A$2:$A$1501) | D37: 122
A38: Enterprise | B38: =COUNTIF('Cleaned Feedback'!$E$2:$E$1501,A38) | C38: =B38/COUNTA('Cleaned Feedback'!$A$2:$A$1501) | D38: 59
A41: Customer Segment | B41: Feedback Records | C41: % of Records | D41: Unique Customers (static)
A42: Mid-Market | B42: =COUNTIF('Cleaned Feedback'!$F$2:$F$1501,A42) | C42: =B42/COUNTA('Cleaned Feedback'!$A$2:$A$1501) | D42: 133
A43: SMB | B43: =COUNTIF('Cleaned Feedback'!$F$2:$F$1501,A43) | C43: =B43/COUNTA('Cleaned Feedback'!$A$2:$A$1501) | D43: 140
A44: Enterprise | B44: =COUNTIF('Cleaned Feedback'!$F$2:$F$1501,A44) | C44: =B44/COUNTA('Cleaned Feedback'!$A$2:$A$1501) | D44: 53
A47: Feedback Source | B47: Feedback Records | C47: % of Records | D47: Unique Customers (static)
A48: Support Ticket | B48: =COUNTIF('Cleaned Feedback'!$D$2:$D$1501,A48) | C48: =B48/COUNTA('Cleaned Feedback'!$A$2:$A$1501) | D48: 218
A49: In-App Feedback | B49: =COUNTIF('Cleaned Feedback'!$D$2:$D$1501,A49) | C49: =B49/COUNTA('Cleaned Feedback'!$A$2:$A$1501) | D49: 199
A50: Feature Request | B50: =COUNTIF('Cleaned Feedback'!$D$2:$D$1501,A50) | C50: =B50/COUNTA('Cleaned Feedback'!$A$2:$A$1501) | D50: 184
A51: Customer Survey | B51: =COUNTIF('Cleaned Feedback'!$D$2:$D$1501,A51) | C51: =B51/COUNTA('Cleaned Feedback'!$A$2:$A$1501) | D51: 194
A54: Month | B54: Feedback Records | C54: Unique Customers (static)
A55: 2025-10 | B55: =COUNTIF('Cleaned Feedback'!$O$2:$O$1501,A55) | C55: 90
...

Sheet Feature Prioritization
A1: Feature Prioritization
A2: SYNTHETIC DATA — all records are randomly generated for a fictional CRM company; no real customers.
A3: Scores/ranks are formulas linked to 'RICE Calculations'. RICE scores are decision aids built on estimates, not objective facts.
A5: Feature ID | B5: Feature Name | C5: Customer Problem | D5: Supporting Feedback Count | E5: Unique Affected Customers | F5: Reach | G5: Impact | H5: Confidence | I5: Effort (pm) | J5: RICE Score | K5: Priority Rank | L5: Recommendation
A6: F01 | B6: Duplicate Detection & Bulk Merge | C6: Duplicate leads and contacts pile up from imports and web forms; teams clean them by hand | D6: ='RICE Calculations'!C9 | E6: ='RICE Calculations'!D9 | F6: ='RICE Calculations'!E9 | G6: ='RICE Calculations'!F9 | H6: ='RICE Calculations'!G9 | I6: ='RICE Calculations'!H9 | J6: ='RICE Calculations'!I9 | K6: ='RICE Calculations'!J9 | L6: Plan next (validate scope)
A7: F02 | B7: Lead Scoring & Smart Routing | C7: Reps prioritise leads by gut feel and routing rules are inflexible | D7: ='RICE Calculations'!C10 | E7: ='RICE Calculations'!D10 | F7: ='RICE Calculations'!E10 | G7: ='RICE Calculations'!F10 | H7: ='RICE Calculations'!G10 | I7: ='RICE Calculations'!H10 | J7: ='RICE Calculations'!I10 | K7: ='RICE Calculations'!J10 | L7: Defer; monitor feedback
A8: F03 | B8: Reliable CSV Import with Validation | C8: Contact imports fail or scramble fields with no row-level error detail | D8: ='RICE Calculations'!C11 | E8: ='RICE Calculations'!D11 | F8: ='RICE Calculations'!E11 | G8: ='RICE Calculations'!F11 | H8: ='RICE Calculations'!G11 | I8: ='RICE Calculations'!H11 | J8: ='RICE Calculations'!I11 | K8: ='RICE Calculations'!J11 | L8: Build now (next planning cycle)
A9: F04 | B9: Workflow Run Monitoring & Failure Alerts | C9: Automations fail silently or misfire and customers learn about it late | D9: ='RICE Calculations'!C12 | E9: ='RICE Calculations'!D12 | F9: ='RICE Calculations'!E12 | G9: ='RICE Calculations'!F12 | H9: ='RICE Calculations'!G12 | I9: ='RICE Calculations'!H12 | J9: ='RICE Calculations'!I12 | K9: ='RICE Calculations'!J12 | L9: Build now (next planning cycle)
A10: F05 | B10: Guided Workflow Builder & Templates | C10: Workflow builder is hard to follow and customers rebuild common flows from scratch | D10: ='RICE Calculations'!C13 | E10: ='RICE Calculations'!D13 | F10: ='RICE Calculations'!E13 | G10: ='RICE Calculations'!F13 | H10: ='RICE Calculations'!G13 | I10: ='RICE Calculations'!H13 | J10: ='RICE Calculations'!I13 | K10: ='RICE Calculations'!J13 | L10: Investigate / discovery first
A11: F06 | B11: Custom & Scheduled Reports with Reliable Export | C11: Managers cannot build their own reports and exports truncate or mismatch | D11: ='RICE Calculations'!C14 | E11: ='RICE Calculations'!D14 | F11: ='RICE Calculations'!E14 | G11: ='RICE Calculations'!F14 | H11: ='RICE Calculations'!G14 | I11: ='RICE Calculations'!H14 | J11: ='RICE Calculations'!I14 | K11: ='RICE Calculations'!J14 | L11: Investigate / discovery first
A12: F07 | B12: Performance Tuning for Dashboards & Lists | C12: Dashboards, lead boards, search and pages are slow with large data | D12: ='RICE Calculations'!C15 | E12: ='RICE Calculations'!D15 | F12: ='RICE Calculations'!E15 | G12: ='RICE Calculations'!F15 | H12: ='RICE Calculations'!G15 | I12: ='RICE Calculations'!H15 | J12: ='RICE Calculations'!I15 | K12: ='RICE Calculations'!J15 | L12: Build now (next planning cycle)
A13: F08 | B13: Email & Calendar Sync Reliability | C13: Gmail/Outlook sync disconnects and drops activities | D13: ='RICE Calculations'!C16 | E13: ='RICE Calculations'!D16 | F13: ='RICE Calculations'!E16 | G13: ='RICE Calculations'!F16 | H13: ='RICE Calculations'!G16 | I13: ='RICE Calculations'!H16 | J13: ='RICE Calculations'!I16 | K13: ='RICE Calculations'!J16 | L13: Plan next (validate scope)
A14: F09 | B14: API & Webhook Reliability Console | C14: Rate limits and failed webhooks are hard to debug with no retry or logs | D14: ='RICE Calculations'!C17 | E14: ='RICE Calculations'!D17 | F14: ='RICE Calculations'!E17 | G14: ='RICE Calculations'!F17 | H14: ='RICE Calculations'!G17 | I14: ='RICE Calculations'!H17 | J14: ='RICE Calculations'!I17 | K14: ='RICE Calculations'!J17 | L14: Plan next (validate scope)
A15: F10 | B15: Native Integrations (Accounting, Marketing, Slack) | C15: Customers maintain Zapier chains and re-enter data across systems | D15: ='RICE Calculations'!C18 | E15: ='RICE Calculations'!D18 | F15: ='RICE Calculations'!E18 | G15: ='RICE Calculations'!F18 | H15: ='RICE Calculations'!G18 | I15: ='RICE Calculations'!H18 | J15: ='RICE Calculations'!I18 | K15: ='RICE Calculations'!J18 | L15: Defer; monitor feedback
A16: F11 | B16: Mobile App | C16: Field reps cannot update deals or log activity away from a desk | D16: ='RICE Calculations'!C19 | E16: ='RICE Calculations'!D19 | F16: ='RICE Calculations'!E19 | G16: ='RICE Calculations'!F19 | H16: ='RICE Calculations'!G19 | I16: ='RICE Calculations'!H19 | J16: ='RICE Calculations'!I19 | K16: ='RICE Calculations'!J19 | L16: Defer; monitor feedback
A17: F12 | B17: Bulk Actions & Simplified Navigation | C17: Records are changed one at a time and navigation is cluttered | D17: ='RICE Calculations'!C20 | E17: ='RICE Calculations'!D20 | F17: ='RICE Calculations'!E20 | G17: ='RICE Calculations'!F20 | H17: ='RICE Calculations'!G20 | I17: ='RICE Calculations'!H20 | J17: ='RICE Calculations'!I20 | K17: ='RICE Calculations'!J20 | L17: Investigate / discovery first

Sheet RICE Calculations
A1: RICE Calculations
A2: SYNTHETIC DATA — all records are randomly generated for a fictional CRM company; no real customers.
A3: Reach window: 2025-10-01 to 2026-09-30 (12 months). RICE = Reach × Impact × Confidence ÷ Effort. Green = observed from data; yellow = analyst ESTIMATE (editable — scores and ranks recalculate).
A5: Reporting multiplier (estimate) | B5: 2.5 | C5: Assumed # of affected accounts represented by each account that reported (feedback under-reports).
A6: Account base / reach cap (observed) | B6: 420 | C6: Accounts in synthetic customer master; Reach cannot exceed this.
A8: Feature ID | B8: Feature Name | C8: Supporting Feedback (observed) | D8: Unique Affected Customers (observed) | E8: Reach (est. accounts/12 mo) | F8: Impact (estimate) | G8: Confidence (estimate) | H8: Effort (person-months, estimate) | I8: RICE Score | J8: Priority Rank | K8: Python RICE (cross-check) | L8: How estimates were chosen
A9: F01 | B9: Duplicate Detection & Bulk Merge | C9: 150 | D9: 118 | E9: =MIN($B$6,ROUND(D9*$B$5,0)) | F9: 1 | G9: 1 | H9: 4 | I9: =ROUND(E9*F9*G9/H9,2) | J9: =RANK(I9,$I$9:$I$20) | K9: 73.75 | L9: Impact 1.0: 37% of supporting records are High/Critical severity or blocking/risk impact (thresholds: >=55%->3, >=40%->2, >=25%->1, >=12%->0.5, else 0.25). Confidence 1.00: 150 records, 4/4 sources, 3/3 plans (rule: 0.5 base +0.1 per evidence criterion) minus tech-risk penalty 0.0. Reach 295: 118 reporting accounts x 2.5 reporting multiplier, capped at the 420-account base. Effort 4.0 person-months: Matching engine + merge UI + history-preserving merge; ~2 engineers for 2 months (analyst estimate)
A10: F02 | B10: Lead Scoring & Smart Routing | C10: 114 | D10: 90 | E10: =MIN($B$6,ROUND(D10*$B$5,0)) | F10: 0.5 | G10: 0.8 | H10: 5 | I10: =ROUND(E10*F10*G10/H10,2) | J10: =RANK(I10,$I$9:$I$20) | K10: 18 | L10: Impact 0.5: 23% of supporting records are High/Critical severity or blocking/risk impact (thresholds: >=55%->3, >=40%->2, >=25%->1, >=12%->0.5, else 0.25). Confidence 0.80: 114 records, 4/4 sources, 3/3 plans (rule: 0.5 base +0.1 per evidence criterion) minus tech-risk penalty 0.1. Reach 225: 90 reporting accounts x 2.5 reporting multiplier, capped at the 420-account base. Effort 5.0 person-months: Rules-based scoring first, routing builder reuse; model quality is uncertain (analyst estimate)
A11: F03 | B11: Reliable CSV Import with Validation | C11: 102 | D11: 86 | E11: =MIN($B$6,ROUND(D11*$B$5,0)) | F11: 2 | G11: 0.9 | H11: 2 | I11: =ROUND(E11*F11*G11/H11,2) | J11: =RANK(I11,$I$9:$I$20) | K11: 193.5 | L11: Impact 2.0: 50% of supporting records are High/Critical severity or blocking/risk impact (thresholds: >=55%->3, >=40%->2, >=25%->1, >=12%->0.5, else 0.25). Confidence 0.90: 102 records, 4/4 sources, 3/3 plans (rule: 0.5 base +0.1 per evidence criterion) minus tech-risk penalty 0.0. Reach 215: 86 reporting accounts x 2.5 reporting multiplier, capped at the 420-account base. Effort 2.0 person-months: Pre-import validation, field-mapping memory, row-level error report (analyst estimate)
A12: F04 | B12: Workflow Run Monitoring & Failure Alerts | C12: 100 | D12: 78 | E12: =MIN($B$6,ROUND(D12*$B$5,0)) | F12: 2 | G12: 0.9 | H12: 2.5 | I12: =ROUND(E12*F12*G12/H12,2) | J12: =RANK(I12,$I$9:$I$20) | K12: 140.4 | L12: Impact 2.0: 53% of supporting records are High/Critical severity or blocking/risk impact (thresholds: >=55%->3, >=40%->2, >=25%->1, >=12%->0.5, else 0.25). Confidence 0.90: 100 records, 4/4 sources, 3/3 plans (rule: 0.5 base +0.1 per evidence criterion) minus tech-risk penalty 0.0. Reach 195: 78 reporting accounts x 2.5 reporting multiplier, capped at the 420-account base. Effort 2.5 person-months: Run log UI, failure alerts, retry controls on existing engine (analyst estimate)
A13: F05 | B13: Guided Workflow Builder & Templates | C13: 166 | D13: 124 | E13: =MIN($B$6,ROUND(D13*$B$5,0)) | F13: 1 | G13: 1 | H13: 5 | I13: =ROUND(E13*F13*G13/H13,2) | J13: =RANK(I13,$I$9:$I$20) | K13: 62 | L13: Impact 1.0: 27% of supporting records are High/Critical severity or blocking/risk impact (thresholds: >=55%->3, >=40%->2, >=25%->1, >=12%->0.5, else 0.25). Confidence 1.00: 166 records, 4/4 sources, 3/3 plans (rule: 0.5 base +0.1 per evidence criterion) minus tech-risk penalty 0.0. Reach 310: 124 reporting accounts x 2.5 reporting multiplier, capped at the 420-account base. Effort 5.0 person-months: Builder UX rework plus 10-15 templates; design-heavy (analyst estimate)
A14: F06 | B14: Custom & Scheduled Reports with Reliable Export | C14: 135 | D14: 96 | E14: =MIN($B$6,ROUND(D14*$B$5,0)) | F14: 1 | G14: 0.8 | H14: 6 | I14: =ROUND(E14*F14*G14/H14,2) | J14: =RANK(I14,$I$9:$I$20) | K14: 32 | L14: Impact 1.0: 39% of supporting records are High/Critical severity or blocking/risk impact (thresholds: >=55%->3, >=40%->2, >=25%->1, >=12%->0.5, else 0.25). Confidence 0.80: 135 records, 4/4 sources, 3/3 plans (rule: 0.5 base +0.1 per evidence criterion) minus tech-risk penalty 0.1. Reach 240: 96 reporting accounts x 2.5 reporting multiplier, capped at the 420-account base. Effort 6.0 person-months: Report builder is a large scope; export fix is small (analyst estimate)
A15: F07 | B15: Performance Tuning for Dashboards & Lists | C15: 189 | D15: 125 | E15: =MIN($B$6,ROUND(D15*$B$5,0)) | F15: 2 | G15: 0.9 | H15: 5 | I15: =ROUND(E15*F15*G15/H15,2) | J15: =RANK(I15,$I$9:$I$20) | K15: 112.68 | L15: Impact 2.0: 44% of supporting records are High/Critical severity or blocking/risk impact (thresholds: >=55%->3, >=40%->2, >=25%->1, >=12%->0.5, else 0.25). Confidence 0.90: 189 records, 4/4 sources, 3/3 plans (rule: 0.5 base +0.1 per evidence criterion) minus tech-risk penalty 0.1. Reach 313: 125 reporting accounts x 2.5 reporting multiplier, capped at the 420-account base. Effort 5.0 person-months: Profiling-driven; root causes unknown until investigated (analyst estimate)
A16: F08 | B16: Email & Calendar Sync Reliability | C16: 88 | D16: 74 | E16: =MIN($B$6,ROUND(D16*$B$5,0)) | F16: 2 | G16: 0.7 | H16: 3 | I16: =ROUND(E16*F16*G16/H16,2) | J16: =RANK(I16,$I$9:$I$20) | K16: 86.33 | L16: Impact 2.0: 50% of supporting records are High/Critical severity or blocking/risk impact (thresholds: >=55%->3, >=40%->2, >=25%->1, >=12%->0.5, else 0.25). Confidence 0.70: 88 records, 4/4 sources, 3/3 plans (rule: 0.5 base +0.1 per evidence criterion) minus tech-risk penalty 0.1. Reach 185: 74 reporting accounts x 2.5 reporting multiplier, capped at the 420-account base. Effort 3.0 person-months: Token refresh, health indicator, backfill job; third-party API quirks (analyst estimate)
A17: F09 | B17: API & Webhook Reliability Console | C17: 65 | D17: 55 | E17: =MIN($B$6,ROUND(D17*$B$5,0)) | F17: 2 | G17: 0.7 | H17: 2.5 | I17: =ROUND(E17*F17*G17/H17,2) | J17: =RANK(I17,$I$9:$I$20) | K17: 77.28 | L17: Impact 2.0: 54% of supporting records are High/Critical severity or blocking/risk impact (thresholds: >=55%->3, >=40%->2, >=25%->1, >=12%->0.5, else 0.25). Confidence 0.70: 65 records, 3/4 sources, 3/3 plans (rule: 0.5 base +0.1 per evidence criterion) minus tech-risk penalty 0.0. Reach 138: 55 reporting accounts x 2.5 reporting multiplier, capped at the 420-account base. Effort 2.5 person-months: Delivery log, retries, rate-limit headers and docs (analyst estimate)
A18: F10 | B18: Native Integrations (Accounting, Marketing, Slack) | C18: 58 | D18: 53 | E18: =MIN($B$6,ROUND(D18*$B$5,0)) | F18: 0.5 | G18: 0.7 | H18: 8 | I18: =ROUND(E18*F18*G18/H18,2) | J18: =RANK(I18,$I$9:$I$20) | K18: 5.82 | L18: Impact 0.5: 24% of supporting records are High/Critical severity or blocking/risk impact (thresholds: >=55%->3, >=40%->2, >=25%->1, >=12%->0.5, else 0.25). Confidence 0.70: 58 records, 4/4 sources, 3/3 plans (rule: 0.5 base +0.1 per evidence criterion) minus tech-risk penalty 0.1. Reach 133: 53 reporting accounts x 2.5 reporting multiplier, capped at the 420-account base. Effort 8.0 person-months: Three connectors with partner reviews (analyst estimate)
A19: F11 | B19: Mobile App | C19: 82 | D19: 68 | E19: =MIN($B$6,ROUND(D19*$B$5,0)) | F19: 0.5 | G19: 0.7 | H19: 12 | I19: =ROUND(E19*F19*G19/H19,2) | J19: =RANK(I19,$I$9:$I$20) | K19: 4.96 | L19: Impact 0.5: 22% of supporting records are High/Critical severity or blocking/risk impact (thresholds: >=55%->3, >=40%->2, >=25%->1, >=12%->0.5, else 0.25). Confidence 0.70: 82 records, 4/4 sources, 3/3 plans (rule: 0.5 base +0.1 per evidence criterion) minus tech-risk penalty 0.1. Reach 170: 68 reporting accounts x 2.5 reporting multiplier, capped at the 420-account base. Effort 12.0 person-months: New client, offline sync, app-store release; largest scope (analyst estimate)
A20: F12 | B20: Bulk Actions & Simplified Navigation | C20: 100 | D20: 84 | E20: =MIN($B$6,ROUND(D20*$B$5,0)) | F20: 1 | G20: 0.9 | H20: 3 | I20: =ROUND(E20*F20*G20/H20,2) | J20: =RANK(I20,$I$9:$I$20) | K20: 63 | L20: Impact 1.0: 26% of supporting records are High/Critical severity or blocking/risk impact (thresholds: >=55%->3, >=40%->2, >=25%->1, >=12%->0.5, else 0.25). Confidence 0.90: 100 records, 4/4 sources, 3/3 plans (rule: 0.5 base +0.1 per evidence criterion) minus tech-risk penalty 0.0. Reach 210: 84 reporting accounts x 2.5 reporting multiplier, capped at the 420-account base. Effort 3.0 person-months: Multi-select framework plus IA changes (analyst estimate)
A23: Sensitivity analysis — priority rank under alternative assumptions (computed in Python)
A24: feature_id | B24: feature_name | C24: Base case | D24: Reporting multiplier 1.5 | E24: Reporting multiplier 4.0 | F24: Reach capped at 250 accounts | G24: Impact from High/Critical severity only | H24: Confidence flat 0.8 | I24: Optimistic effort (low estimates) | J24: Pessimistic effort (high estimates) | K24: Best rank | L24: Worst rank
A25: F03 | B25: Reliable CSV Import with Validation | C25: 1 | D25: 1 | E25: 1 | F25: 1 | G25: 1 | H25: 1 | I25: 1 | J25: 1 | K25: 1 | L25: 1
A26: F04 | B26: Workflow Run Monitoring & Failure Alerts | C26: 2 | D26: 2 | E26: 2 | F26: 2 | G26: 2 | H26: 2 | I26: 3 | J26: 2 | K26: 2 | L26: 3
A27: F07 | B27: Performance Tuning for Dashboards & Lists | C27: 3 | D27: 3 | E27: 3 | F27: 3 | G27: 5 | H27: 3 | I27: 2 | J27: 3 | K27: 2 | L27: 5
A28: F08 | B28: Email & Calendar Sync Reliability | C28: 4 | D28: 4 | E28: 4 | F28: 4 | G28: 6 | H28: 4 | I28: 4 | J28: 4 | K28: 4 | L28: 6
A29: F09 | B29: API & Webhook Reliability Console | C29: 5 | D29: 5 | E29: 5 | F29: 5 | G29: 3 | H29: 5 | I29: 6 | J29: 6 | K29: 3 | L29: 6
A30: F01 | B30: Duplicate Detection & Bulk Merge | C30: 6 | D30: 6 | E30: 6 | F30: 7 | G30: 4 | H30: 6 | I30: 5 | J30: 5 | K30: 4 | L30: 7
A31: F12 | B31: Bulk Actions & Simplified Navigation | C31: 7 | D31: 7 | E31: 7 | F31: 6 | G31: 8 | H31: 7 | I31: 7 | J31: 8 | K31: 6 | L31: 8
A32: F05 | B32: Guided Workflow Builder & Templates | C32: 8 | D32: 8 | E32: 8 | F32: 8 | G32: 9 | H32: 8 | I32: 8 | J32: 7 | K32: 7 | L32: 9
A33: F06 | B33: Custom & Scheduled Reports with Reliable Export | C33: 9 | D33: 9 | E33: 9 | F33: 9 | G33: 7 | H33: 9 | I33: 9 | J33: 9 | K33: 7 | L33: 9
A34: F02 | B34: Lead Scoring & Smart Routing | C34: 10 | D34: 10 | E34: 10 | F34: 10 | G34: 10 | H34: 10 | I34: 10 | J34: 10 | K34: 10 | L34: 10
A35: F10 | B35: Native Integrations (Accounting, Marketing, Slack) | C35: 11 | D35: 11 | E35: 11 | F35: 11 | G35: 11 | H35: 11 | I35: 11 | J35: 11 | K35: 11 | L35: 11
A36: F11 | B36: Mobile App | C36: 12 | D36: 12 | E36: 12 | F36: 12 | G36: 12 | H36: 12 | I36: 12 | J36: 12 | K36: 12 | L36: 12
A39: Monte Carlo rank stability — 5000 trials, each of R, I, C, E perturbed ±30% (uniform, seed 7)
A40: Feature ID | B40: feature_name | C40: base_rank | D40: median_rank | E40: p10_rank | F40: p90_rank | G40: prob_top3_pct | H40: prob_rank1_pct
A41: F03 | B41: Reliable CSV Import with Validation | C41: 1 | D41: 1 | E41: 1 | F41: 3 | G41: 96.1 | H41: 65.8
A42: F04 | B42: Workflow Run Monitoring & Failure Alerts | C42: 2 | D42: 2 | E42: 1 | F42: 4 | G42: 80.6 | H42: 22.2
A43: F07 | B43: Performance Tuning for Dashboards & Lists | C43: 3 | D43: 3 | E43: 2 | F43: 6 | G43: 57.6 | H43: 8.1
A44: F08 | B44: Email & Calendar Sync Reliability | C44: 4 | D44: 5 | E44: 2 | F44: 7 | G44: 28.8 | H44: 2.3
A45: F09 | B45: API & Webhook Reliability Console | C45: 5 | D45: 5 | E45: 3 | F45: 8 | G45: 18.6 | H45: 1.1
A46: F01 | B46: Duplicate Detection & Bulk Merge | C46: 6 | D46: 6 | E46: 4 | F46: 8 | G46: 9.6 | H46: 0.4
...

Sheet Product Recommendations
A1: Product Recommendations
A2: SYNTHETIC DATA — all records are randomly generated for a fictional CRM company; no real customers.
A3: Hypotheses for the product team, derived from RICE ranks and the feedback analysis; not validated outcomes.
A5: Priority | B5: Feature | C5: Recommendation | D5: Why (observed data) | E5: Open risk / what to validate
A6: 1 | B6: F03 Reliable CSV Import with Validation | C6: Build now (next planning cycle) | D6: 102 records from 86 accounts; 50% High/Critical or blocking; RICE 193.5 | E6: Rank stable across scenarios
A7: 2 | B7: F04 Workflow Run Monitoring & Failure Alerts | C7: Build now (next planning cycle) | D7: 100 records from 78 accounts; 53% High/Critical or blocking; RICE 140.4 | E7: Rank stable across scenarios
A8: 3 | B8: F07 Performance Tuning for Dashboards & Lists | C8: Build now (next planning cycle) | D8: 189 records from 125 accounts; 44% High/Critical or blocking; RICE 112.68 | E8: Rank is sensitive to effort estimate
A9: 4 | B9: F08 Email & Calendar Sync Reliability | C9: Plan next (validate scope) | D9: 88 records from 74 accounts; 50% High/Critical or blocking; RICE 86.33 | E9: Rank stable across scenarios
A10: 5 | B10: F09 API & Webhook Reliability Console | C10: Plan next (validate scope) | D10: 65 records from 55 accounts; 54% High/Critical or blocking; RICE 77.28 | E10: Rank is sensitive to effort estimate
A11: 6 | B11: F01 Duplicate Detection & Bulk Merge | C11: Plan next (validate scope) | D11: 150 records from 118 accounts; 37% High/Critical or blocking; RICE 73.75 | E11: Rank is sensitive to effort estimate
A12: 7 | B12: F12 Bulk Actions & Simplified Navigation | C12: Investigate / discovery first | D12: 100 records from 84 accounts; 26% High/Critical or blocking; RICE 63 | E12: Rank stable across scenarios
A13: 8 | B13: F05 Guided Workflow Builder & Templates | C13: Investigate / discovery first | D13: 166 records from 124 accounts; 27% High/Critical or blocking; RICE 62 | E13: Rank stable across scenarios
A14: 9 | B14: F06 Custom & Scheduled Reports with Reliable Export | C14: Investigate / discovery first | D14: 135 records from 96 accounts; 39% High/Critical or blocking; RICE 32 | E14: Rank stable across scenarios
A15: 10 | B15: F02 Lead Scoring & Smart Routing | C15: Defer; monitor feedback | D15: 114 records from 90 accounts; 23% High/Critical or blocking; RICE 18 | E15: Rank stable across scenarios
A16: 11 | B16: F10 Native Integrations (Accounting, Marketing, Slack) | C16: Defer; monitor feedback | D16: 58 records from 53 accounts; 24% High/Critical or blocking; RICE 5.82 | E16: Rank stable across scenarios
A17: 12 | B17: F11 Mobile App | C17: Defer; monitor feedback | D17: 82 records from 68 accounts; 22% High/Critical or blocking; RICE 4.96 | E17: Rank stable across scenarios
